Workbook

Sheet 📊 자산 조회 대시보드
A1: K — 자산 현황 조회 (년월 입력)
A3: 조회 연도 | B3: 2014 | C3: 조회 월 | D3: 6 | E3: ← 연도/월 입력 후 자산 현황 확인
A5: 자산 구분 | B5: 세부 항목 | C5: 보유 수량 | D5: 단가 ($) | E5: 평가액 ($M) | F5: 비고
A6: 주식 | B6: AMZN | C6: =IFERROR(VLOOKUP($B$3,주식보유수량!$A:$ZZ,MATCH("AMZN",주식보유수량!$1:$1,0),TRUE),"-") | D6: =IFERROR(VLOOKUP($B$3,주식연도별가격!$A:$ZZ,MATCH("AMZN",주식연도별가격!$1:$1,0),TRUE),"-") | E6: =IFERROR(IF(C6="-",0,C6*D6/1000000),0) | F6: 연도 평균가 기준
A7: 주식 | B7: AAPL | C7: =IFERROR(VLOOKUP($B$3,주식보유수량!$A:$ZZ,MATCH("AAPL",주식보유수량!$1:$1,0),TRUE),"-") | D7: =IFERROR(VLOOKUP($B$3,주식연도별가격!$A:$ZZ,MATCH("AAPL",주식연도별가격!$1:$1,0),TRUE),"-") | E7: =IFERROR(IF(C7="-",0,C7*D7/1000000),0) | F7: 연도 평균가 기준
A8: 주식 | B8: GOOG | C8: =IFERROR(VLOOKUP($B$3,주식보유수량!$A:$ZZ,MATCH("GOOG",주식보유수량!$1:$1,0),TRUE),"-") | D8: =IFERROR(VLOOKUP($B$3,주식연도별가격!$A:$ZZ,MATCH("GOOG",주식연도별가격!$1:$1,0),TRUE),"-") | E8: =IFERROR(IF(C8="-",0,C8*D8/1000000),0) | F8: 연도 평균가 기준
A9: 주식 | B9: NVDA | C9: =IFERROR(VLOOKUP($B$3,주식보유수량!$A:$ZZ,MATCH("NVDA",주식보유수량!$1:$1,0),TRUE),"-") | D9: =IFERROR(VLOOKUP($B$3,주식연도별가격!$A:$ZZ,MATCH("NVDA",주식연도별가격!$1:$1,0),TRUE),"-") | E9: =IFERROR(IF(C9="-",0,C9*D9/1000000),0) | F9: 연도 평균가 기준
A10: 주식 | B10: NFLX | C10: =IFERROR(VLOOKUP($B$3,주식보유수량!$A:$ZZ,MATCH("NFLX",주식보유수량!$1:$1,0),TRUE),"-") | D10: =IFERROR(VLOOKUP($B$3,주식연도별가격!$A:$ZZ,MATCH("NFLX",주식연도별가격!$1:$1,0),TRUE),"-") | E10: =IFERROR(IF(C10="-",0,C10*D10/1000000),0) | F10: 연도 평균가 기준
A11: 주식 | B11: TSLA | C11: =IFERROR(VLOOKUP($B$3,주식보유수량!$A:$ZZ,MATCH("TSLA",주식보유수량!$1:$1,0),TRUE),"-") | D11: =IFERROR(VLOOKUP($B$3,주식연도별가격!$A:$ZZ,MATCH("TSLA",주식연도별가격!$1:$1,0),TRUE),"-") | E11: =IFERROR(IF(C11="-",0,C11*D11/1000000),0) | F11: 연도 평균가 기준
A12: 주식 | B12: BABA | C12: =IFERROR(VLOOKUP($B$3,주식보유수량!$A:$ZZ,MATCH("BABA",주식보유수량!$1:$1,0),TRUE),"-") | D12: =IFERROR(VLOOKUP($B$3,주식연도별가격!$A:$ZZ,MATCH("BABA",주식연도별가격!$1:$1,0),TRUE),"-") | E12: =IFERROR(IF(C12="-",0,C12*D12/1000000),0) | F12: 연도 평균가 기준
A13: 주식 | B13: AMD | C13: =IFERROR(VLOOKUP($B$3,주식보유수량!$A:$ZZ,MATCH("AMD",주식보유수량!$1:$1,0),TRUE),"-") | D13: =IFERROR(VLOOKUP($B$3,주식연도별가격!$A:$ZZ,MATCH("AMD",주식연도별가격!$1:$1,0),TRUE),"-") | E13: =IFERROR(IF(C13="-",0,C13*D13/1000000),0) | F13: 연도 평균가 기준
A14: 주식 | B14: META | C14: =IFERROR(VLOOKUP($B$3,주식보유수량!$A:$ZZ,MATCH("META",주식보유수량!$1:$1,0),TRUE),"-") | D14: =IFERROR(VLOOKUP($B$3,주식연도별가격!$A:$ZZ,MATCH("META",주식연도별가격!$1:$1,0),TRUE),"-") | E14: =IFERROR(IF(C14="-",0,C14*D14/1000000),0) | F14: 연도 평균가 기준
A15: 주식 | B15: MSFT | C15: =IFERROR(VLOOKUP($B$3,주식보유수량!$A:$ZZ,MATCH("MSFT",주식보유수량!$1:$1,0),TRUE),"-") | D15: =IFERROR(VLOOKUP($B$3,주식연도별가격!$A:$ZZ,MATCH("MSFT",주식연도별가격!$1:$1,0),TRUE),"-") | E15: =IFERROR(IF(C15="-",0,C15*D15/1000000),0) | F15: 연도 평균가 기준
A16: 주식 | B16: 텐센트 | C16: =IFERROR(VLOOKUP($B$3,주식보유수량!$A:$ZZ,MATCH("텐센트",주식보유수량!$1:$1,0),TRUE),"-") | D16: =IFERROR(VLOOKUP($B$3,주식연도별가격!$A:$ZZ,MATCH("텐센트",주식연도별가격!$1:$1,0),TRUE),"-") | E16: =IFERROR(IF(C16="-",0,C16*D16/1000000),0) | F16: 연도 평균가 기준
A17: 주식 | B17: AVGO | C17: =IFERROR(VLOOKUP($B$3,주식보유수량!$A:$ZZ,MATCH("AVGO",주식보유수량!$1:$1,0),TRUE),"-") | D17: =IFERROR(VLOOKUP($B$3,주식연도별가격!$A:$ZZ,MATCH("AVGO",주식연도별가격!$1:$1,0),TRUE),"-") | E17: =IFERROR(IF(C17="-",0,C17*D17/1000000),0) | F17: 연도 평균가 기준
A18: 주식 소계 | E18: =SUM(E6:E17)
A19: 코인 | B19: BTC(사토시) | C19: =IFERROR(VLOOKUP($B$3,코인보유수량!$A:$ZZ,MATCH("BTC(사토시)",코인보유수량!$1:$1,0),TRUE),"-") | D19: =IFERROR(VLOOKUP($B$3,코인연도별가격!$A:$ZZ,MATCH("BTC(사토시)",코인연도별가격!$1:$1,0),TRUE),"-") | E19: =IFERROR(IF(C19="-",0,C19*D19/1000000),0) | F19: 연도 평균가 기준
A20: 코인 | B20: BTC(별도) | C20: =IFERROR(VLOOKUP($B$3,코인보유수량!$A:$ZZ,MATCH("BTC(별도)",코인보유수량!$1:$1,0),TRUE),"-") | D20: =IFERROR(VLOOKUP($B$3,코인연도별가격!$A:$ZZ,MATCH("BTC(별도)",코인연도별가격!$1:$1,0),TRUE),"-") | E20: =IFERROR(IF(C20="-",0,C20*D20/1000000),0) | F20: 연도 평균가 기준
A21: 코인 | B21: ETH | C21: =IFERROR(VLOOKUP($B$3,코인보유수량!$A:$ZZ,MATCH("ETH",코인보유수량!$1:$1,0),TRUE),"-") | D21: =IFERROR(VLOOKUP($B$3,코인연도별가격!$A:$ZZ,MATCH("ETH",코인연도별가격!$1:$1,0),TRUE),"-") | E21: =IFERROR(IF(C21="-",0,C21*D21/1000000),0) | F21: 연도 평균가 기준
A22: 코인 | B22: BNB | C22: =IFERROR(VLOOKUP($B$3,코인보유수량!$A:$ZZ,MATCH("BNB",코인보유수량!$1:$1,0),TRUE),"-") | D22: =IFERROR(VLOOKUP($B$3,코인연도별가격!$A:$ZZ,MATCH("BNB",코인연도별가격!$1:$1,0),TRUE),"-") | E22: =IFERROR(IF(C22="-",0,C22*D22/1000000),0) | F22: 연도 평균가 기준
A23: 코인 | B23: SOL | C23: =IFERROR(VLOOKUP($B$3,코인보유수량!$A:$ZZ,MATCH("SOL",코인보유수량!$1:$1,0),TRUE),"-") | D23: =IFERROR(VLOOKUP($B$3,코인연도별가격!$A:$ZZ,MATCH("SOL",코인연도별가격!$1:$1,0),TRUE),"-") | E23: =IFERROR(IF(C23="-",0,C23*D23/1000000),0) | F23: 연도 평균가 기준
A24: 코인 | B24: XRP | C24: =IFERROR(VLOOKUP($B$3,코인보유수량!$A:$ZZ,MATCH("XRP",코인보유수량!$1:$1,0),TRUE),"-") | D24: =IFERROR(VLOOKUP($B$3,코인연도별가격!$A:$ZZ,MATCH("XRP",코인연도별가격!$1:$1,0),TRUE),"-") | E24: =IFERROR(IF(C24="-",0,C24*D24/1000000),0) | F24: 연도 평균가 기준
A25: 코인 | B25: LINK | C25: =IFERROR(VLOOKUP($B$3,코인보유수량!$A:$ZZ,MATCH("LINK",코인보유수량!$1:$1,0),TRUE),"-") | D25: =IFERROR(VLOOKUP($B$3,코인연도별가격!$A:$ZZ,MATCH("LINK",코인연도별가격!$1:$1,0),TRUE),"-") | E25: =IFERROR(IF(C25="-",0,C25*D25/1000000),0) | F25: 연도 평균가 기준
A26: 코인 소계 | E26: =SUM(E19:E25)
A27: 부동산 | B27: 부동산 보유 평가액 | C27: - | D27: - | E27: =IFERROR(VLOOKUP($B$3,연도별기타자산!$A:$D,2,TRUE),0) | F27: 연도 평균 기준
A28: 선물/숏/원자재 | B28: 누적 운용 자산 | C28: - | D28: - | E28: =IFERROR(VLOOKUP($B$3,연도별기타자산!$A:$D,3,TRUE),0) | F28: 연도 평균 기준
A29: 운용사 지분 | B29: 지분 평가액 | C29: - | D29: - | E29: =IFERROR(VLOOKUP($B$3,연도별기타자산!$A:$D,4,TRUE),0) | F29: 연도 평균 기준
A30: 활동자금 차감 | B30: 2005년 차감 (-$750M) | C30: - | D30: - | E30: =IF($B$3>=2005,-750,0) | F30: 연도 평균 기준
A31: ▶ 총 자산 합계 | E31: =E18+E26+SUM(E27:E30)

Sheet 주식보유수량
A1: 주식 보유 수량 — 연도별 (VLOOKUP용)
A2: 연도 | B2: AMZN | C2: AAPL | D2: GOOG | E2: NVDA | F2: NFLX | G2: TSLA | H2: BABA | I2: AMD | J2: META | K2: MSFT | L2: 텐센트 | M2: AVGO
A3: 1999 | B3: 0 | C3: 0 | D3: 0 | E3: 80000000 | F3: 0 | G3: 0 | H3: 0 | I3: 0 | J3: 0 | K3: 0 | L3: 0 | M3: 0
A4: 2000 | B4: 800000 | C4: 8000000 | D4: 0 | E4: 80000000 | F4: 0 | G4: 0 | H4: 0 | I4: 0 | J4: 0 | K4: 0 | L4: 0 | M4: 0
A5: 2001 | B5: 800000 | C5: 8000000 | D5: 0 | E5: 80000000 | F5: 0 | G5: 0 | H5: 0 | I5: 0 | J5: 0 | K5: 0 | L5: 0 | M5: 0
A6: 2002 | B6: 1000000 | C6: 10000000 | D6: 0 | E6: 80000000 | F6: 0 | G6: 0 | H6: 0 | I6: 0 | J6: 0 | K6: 0 | L6: 0 | M6: 0
A7: 2003 | B7: 1000000 | C7: 10000000 | D7: 500000 | E7: 80000000 | F7: 5000000 | G7: 0 | H7: 0 | I7: 0 | J7: 0 | K7: 0 | L7: 0 | M7: 0
A8: 2004 | B8: 1000000 | C8: 10000000 | D8: 700000 | E8: 80000000 | F8: 5000000 | G8: 0 | H8: 0 | I8: 0 | J8: 0 | K8: 0 | L8: 0 | M8: 0
A9: 2005 | B9: 1000000 | C9: 10000000 | D9: 700000 | E9: 80000000 | F9: 5000000 | G9: 0 | H9: 0 | I9: 0 | J9: 0 | K9: 0 | L9: 0 | M9: 0
A10: 2006 | B10: 1000000 | C10: 10000000 | D10: 700000 | E10: 80000000 | F10: 5000000 | G10: 0 | H10: 0 | I10: 0 | J10: 0 | K10: 0 | L10: 70000000 | M10: 0
A11: 2007 | B11: 1000000 | C11: 10000000 | D11: 700000 | E11: 80000000 | F11: 5000000 | G11: 0 | H11: 0 | I11: 0 | J11: 0 | K11: 0 | L11: 70000000 | M11: 0
A12: 2008 | B12: 1000000 | C12: 10000000 | D12: 700000 | E12: 80000000 | F12: 5000000 | G12: 0 | H12: 0 | I12: 0 | J12: 0 | K12: 0 | L12: 70000000 | M12: 0
A13: 2009 | B13: 1000000 | C13: 10000000 | D13: 700000 | E13: 80000000 | F13: 5000000 | G13: 0 | H13: 0 | I13: 0 | J13: 0 | K13: 0 | L13: 70000000 | M13: 0
A14: 2010 | B14: 1000000 | C14: 10000000 | D14: 700000 | E14: 80000000 | F14: 5000000 | G14: 0 | H14: 0 | I14: 0 | J14: 0 | K14: 0 | L14: 70000000 | M14: 0
... A28: 2024 | B28: 500000 | C28: 5000000 | D28: 350000 | E28: 20000000 | F28: 2500000 | G28: 4000000 | H28: 800000 | I28: 15000000 | J28: 6000000 | K28: 7000000 | L28: 55000000 | M28: 3000000

Sheet 주식연도별가격
A1: 주식 연도별 평균가 ($) — 분할조정 반영
A2: 연도 | B2: AMZN | C2: AAPL | D2: GOOG | E2: NVDA | F2: NFLX | G2: TSLA | H2: BABA | I2: AMD | J2: META | K2: MSFT | L2: 텐센트 | M2: AVGO
A3: 1999 | B3: 5 | C3: 0.7 | D3: 0 | E3: 0.04 | F3: 0 | G3: 0 | H3: 0 | I3: 0 | J3: 0 | K3: 35 | L3: 0.1 | M3: 0
A4: 2000 | B4: 20 | C4: 1 | D4: 0 | E4: 0.25 | F4: 0 | G4: 0 | H4: 0 | I4: 0 | J4: 0 | K4: 22 | L4: 0.15 | M4: 0
A5: 2001 | B5: 8 | C5: 0.7 | D5: 0 | E5: 0.12 | F5: 0 | G5: 0 | H5: 0 | I5: 0 | J5: 0 | K5: 26 | L5: 0.2 | M5: 0
A6: 2002 | B6: 12 | C6: 0.9 | D6: 0 | E6: 0.08 | F6: 0 | G6: 0 | H6: 0 | I6: 0 | J6: 0 | K6: 24 | L6: 0.3 | M6: 0
A7: 2003 | B7: 27 | C7: 1.1 | D7: 0 | E7: 0.15 | F7: 0 | G7: 0 | H7: 0 | I7: 0 | J7: 0 | K7: 26 | L7: 0.5 | M7: 0
A8: 2004 | B8: 44 | C8: 1.8 | D8: 100 | E8: 0.35 | F8: 0 | G8: 0 | H8: 0 | I8: 0 | J8: 0 | K8: 28 | L8: 1 | M8: 0
A9: 2005 | B9: 47 | C9: 2.5 | D9: 150 | E9: 0.5 | F9: 0 | G9: 0 | H9: 0 | I9: 0 | J9: 0 | K9: 26 | L9: 1.5 | M9: 0
A10: 2006 | B10: 37 | C10: 3.8 | D10: 230 | E10: 0.65 | F10: 0 | G10: 0 | H10: 0 | I10: 0 | J10: 0 | K10: 24 | L10: 2.5 | M10: 0
A11: 2007 | B11: 90 | C11: 5.5 | D11: 360 | E11: 0.8 | F11: 0 | G11: 0 | H11: 0 | I11: 0 | J11: 0 | K11: 30 | L11: 5 | M11: 0
A12: 2008 | B12: 48 | C12: 3.5 | D12: 220 | E12: 0.45 | F12: 0 | G12: 0 | H12: 0 | I12: 0 | J12: 0 | K12: 20 | L12: 3.5 | M12: 0
A13: 2009 | B13: 135 | C13: 5.5 | D13: 310 | E13: 0.55 | F13: 0 | G13: 0 | H13: 0 | I13: 0 | J13: 0 | K13: 28 | L13: 5.5 | M13: 0
A14: 2010 | B14: 180 | C14: 9 | D14: 430 | E14: 0.6 | F14: 0 | G14: 0 | H14: 0 | I14: 0 | J14: 0 | K14: 27 | L14: 8 | M14: 0
... A28: 2024 | B28: 2100 | C28: 210 | D28: 1700 | E28: 88 | F28: 650 | G28: 250 | H28: 80 | I28: 175 | J28: 490 | K28: 420 | L28: 42 | M28: 1700

Sheet 코인보유수량
A1: 코인 보유 수량 — 연도별 (VLOOKUP용)
A2: 연도 | B2: BTC(사토시) | C2: BTC(별도) | D2: ETH | E2: BNB | F2: SOL | G2: XRP | H2: LINK
A3: 2009 | B3: 1000000 | C3: 0 | D3: 0 | E3: 0 | F3: 0 | G3: 0 | H3: 0
A4: 2010 | B4: 1000000 | C4: 500000 | D4: 0 | E4: 0 | F4: 0 | G4: 0 | H4: 0
A5: 2011 | B5: 1000000 | C5: 500000 | D5: 0 | E5: 0 | F5: 0 | G5: 0 | H5: 0
A6: 2012 | B6: 1000000 | C6: 500000 | D6: 0 | E6: 0 | F6: 0 | G6: 0 | H6: 0
A7: 2013 | B7: 1000000 | C7: 300000 | D7: 0 | E7: 0 | F7: 0 | G7: 100000000 | H7: 0
A8: 2014 | B8: 1000000 | C8: 300000 | D8: 0 | E8: 0 | F8: 0 | G8: 150000000 | H8: 0
A9: 2015 | B9: 1000000 | C9: 600000 | D9: 3000000 | E9: 0 | F9: 0 | G9: 150000000 | H9: 0
A10: 2016 | B10: 1000000 | C10: 600000 | D10: 3000000 | E10: 0 | F10: 0 | G10: 150000000 | H10: 0
A11: 2017 | B11: 1000000 | C11: 400000 | D11: 3000000 | E11: 10000000 | F11: 0 | G11: 150000000 | H11: 20000000
A12: 2018 | B12: 1000000 | C12: 700000 | D12: 2000000 | E12: 7000000 | F12: 0 | G12: 70000000 | H12: 20000000
A13: 2019 | B13: 1000000 | C13: 700000 | D13: 2000000 | E13: 7000000 | F13: 0 | G13: 70000000 | H13: 20000000
A14: 2020 | B14: 1000000 | C14: 500000 | D14: 3000000 | E14: 7000000 | F14: 7000000 | G14: 130000000 | H14: 20000000
... A18: 2024 | B18: 1000000 | C18: 350000 | D18: 2500000 | E18: 10000000 | F18: 5500000 | G18: 150000000 | H18: 22000000

Sheet 코인연도별가격
A1: 코인 연도별 평균가 ($)
A2: 연도 | B2: BTC(사토시) | C2: BTC(별도) | D2: ETH | E2: BNB | F2: SOL | G2: XRP | H2: LINK
A3: 2009 | B3: 0.001 | C3: 0.001 | D3: 0 | E3: 0 | F3: 0 | G3: 0 | H3: 0
A4: 2010 | B4: 0.08 | C4: 0.08 | D4: 0 | E4: 0 | F4: 0 | G4: 0 | H4: 0
A5: 2011 | B5: 5 | C5: 5 | D5: 0 | E5: 0 | F5: 0 | G5: 0 | H5: 0
A6: 2012 | B6: 8 | C6: 8 | D6: 0 | E6: 0 | F6: 0 | G6: 0 | H6: 0
A7: 2013 | B7: 200 | C7: 200 | D7: 0 | E7: 0 | F7: 0 | G7: 0.04 | H7: 0
A8: 2014 | B8: 450 | C8: 450 | D8: 0 | E8: 0 | F8: 0 | G8: 0.01 | H8: 0
A9: 2015 | B9: 280 | C9: 280 | D9: 0.9 | E9: 0 | F9: 0 | G9: 0.005 | H9: 0
A10: 2016 | B10: 570 | C10: 570 | D10: 11 | E10: 0 | F10: 0 | G10: 0.006 | H10: 0
A11: 2017 | B11: 4000 | C11: 4000 | D11: 300 | E11: 5 | F11: 0 | G11: 0.25 | H11: 0.5
A12: 2018 | B12: 7500 | C12: 7500 | D12: 480 | E12: 15 | F12: 0 | G12: 0.4 | H12: 2.5
A13: 2019 | B13: 7200 | C13: 7200 | D13: 180 | E13: 25 | F13: 0 | G13: 0.3 | H13: 2.5
A14: 2020 | B14: 11000 | C14: 11000 | D14: 400 | E14: 25 | F14: 1.5 | G14: 0.25 | H14: 12
... A18: 2024 | B18: 55000 | C18: 55000 | D18: 2800 | E18: 380 | F18: 150 | G18: 0.6 | H18: 15

Sheet 연도별기타자산
A1: 연도별 기타 자산 ($M) — 부동산/선물누적/운용사지분
A2: 연도 | B2: 부동산 ($M) | C2: 선물/숏/원자재 ($M) | D2: 운용사 지분 ($M)
A3: 1998 | B3: 0 | C3: 2.5 | D3: 0
A4: 1999 | B4: 0 | C4: 60 | D4: 0
A5: 2000 | B5: 0 | C5: 150 | D5: 0
A6: 2001 | B6: 45 | C6: 400 | D6: 0
A7: 2002 | B7: 55 | C7: 680 | D7: 0
A8: 2003 | B8: 80 | C8: 1200 | D8: 0
A9: 2004 | B9: 120 | C9: 2400 | D9: 0
A10: 2005 | B10: 150 | C10: 3450 | D10: 50
A11: 2006 | B11: 200 | C11: 6350 | D11: 150
A12: 2007 | B12: 400 | C12: 10200 | D12: 300
A13: 2008 | B13: 200 | C13: 34000 | D13: 500
A14: 2009 | B14: 300 | C14: 48000 | D14: 800
... A29: 2024 | B29: 620 | C29: 37444096 | D29: 40000

Sheet 연도별 자산 스냅샷
A1: K — 연도별 자산 스냅샷 요약 ($M)
A2: 연도 | B2: 주식 ($M) | C2: 코인 ($M) | D2: 부동산 ($M) | E2: 선물/숏/원자재 ($M) | F2: 운용사 지분 ($M) | G2: 활동자금 차감 ($M) | H2: 총합 ($M)
A3: 1998 | B3: 0 | C3: 0 | D3: 0 | E3: 2.5 | F3: 0 | G3: 0 | H3: =SUM(B3:G3)
A4: 1999 | B4: 0 | C4: 0 | D4: 0 | E4: 60 | F4: 0 | G4: 0 | H4: =SUM(B4:G4)
A5: 2000 | B5: 10 | C5: 0 | D5: 0 | E5: 150 | F5: 0 | G5: 0 | H5: =SUM(B5:G5)
A6: 2001 | B6: 15 | C6: 0 | D6: 45 | E6: 400 | F6: 0 | G6: 0 | H6: =SUM(B6:G6)
A7: 2002 | B7: 25 | C7: 0 | D7: 55 | E7: 680 | F7: 0 | G7: 0 | H7: =SUM(B7:G7)
A8: 2003 | B8: 80 | C8: 0 | D8: 80 | E8: 1200 | F8: 0 | G8: 0 | H8: =SUM(B8:G8)
A9: 2004 | B9: 313 | C9: 0 | D9: 120 | E9: 2400 | F9: 0 | G9: 0 | H9: =SUM(B9:G9)
A10: 2005 | B10: 500 | C10: 0 | D10: 150 | E10: 3450 | F10: 50 | G10: -750 | H10: =SUM(B10:G10)
A11: 2006 | B11: 700 | C11: 0 | D11: 200 | E11: 6350 | F11: 150 | G11: -750 | H11: =SUM(B11:G11)
A12: 2007 | B12: 1000 | C12: 0 | D12: 400 | E12: 10200 | F12: 300 | G12: -750 | H12: =SUM(B12:G12)
A13: 2008 | B13: 400 | C13: 0 | D13: 200 | E13: 34000 | F13: 500 | G13: -750 | H13: =SUM(B13:G13)
A14: 2009 | B14: 820 | C14: 0 | D14: 300 | E14: 48000 | F14: 800 | G14: -750 | H14: =SUM(B14:G14)
... A28: 2023 | B28: 46000 | C28: 130000 | D28: 620 | E28: 37444096 | F28: 40000 | G28: -750 | H28: =SUM(B28:G28)
A29: 2024 | B29: 진행중 | C29: 진행중 | D29: 진행중 | E29: 진행중 | F29: 진행중 | G29: 진행중 | H29: EQUILIBRIUM 진행 중
A30: 2025 | B30: 진행중 | C30: 진행중 | D30: 진행중 | E30: 진행중 | F30: 진행중 | G30: 진행중 | H30: EQUILIBRIUM 진행 중
A31: 2026 | B31: 미확정 | C31: 미확정 | D31: 미확정 | E31: 미확정 | F31: 미확정 | G31: 미확정 | H31: EQUILIBRIUM 완료 / 100경원 확정 (2026.06)

Sheet 글로벌 위기 숏 포지션
A1: K — 글로벌 위기 숏 포지션 (20배 레버리지)
A2: 구분 | B2: 시기 | C2: 대상 | D2: 레버리지 | E2: 진입 | F2: 청산 | G2: 하락폭 | H2: 투입시드($M) | I2: 수익($M)
A3: 1차 | B3: 2000.03~2002 | C3: S&P500/나스닥 선물 | D3: 20배 | E3: 나스닥5,000 | F3: 나스닥1,100 | G3: -78% | H3: 500 | I3: 9000
A4: 2차 | B4: 2008.06~2009 | C4: S&P500/금융주/CDS | D4: 20배 | E4: S&P 1,350 | F4: S&P 680 | G4: -49% | H4: 2000 | I4: 22000
A5: 3차 | B5: 2020.02~03 | C5: S&P500/항공·에너지 | D5: 20배 | E5: S&P 3,350 | F5: S&P 2,200 | G5: -34% | H5: 5000 | I5: 54000
A6: 4차 | B6: 2022.01~10 | C6: 나스닥/테크/채권선물 | D6: 20배 | E6: 나스닥16,000 | F6: 나스닥10,500 | G6: -34% | H6: 10000 | I6: 78000
A7: 5차 | B7: 2022.04~11 | C7: BTC/ETH/알트선물 | D7: 20배 | E7: BTC $45,000 | F7: BTC $16,000 | G7: -64% | H7: 5000 | I7: 69000
A8: 합계 | H8: =SUM(H3:H7) | I8: =SUM(I3:I7)

Sheet 알트코인 운용 수익
A1: K — 알트코인 매집/매도 내역
A2: 종목 | B2: 구분 | C2: 시기 | D2: 단가($) | E2: 수량 | F2: 거래금액($M) | G2: 누적매도차익($M) | H2: 2024초 평가액($M)
A3: ETH | B3: 최초매집 | C3: 2015.07 | D3: 0.3 | E3: 2,000,000 | F3: 0.6 | G3: - | H3: -
A4: ETH | B4: 추가매집 | C4: 2016 | D4: 1 | E4: 1,000,000 | F4: 1 | G4: - | H4: -
A5: ETH | B5: 1차매도 | C5: 2018.01 | D5: 1400 | E5: 1,000,000 | F5: 1400 | G5: - | H5: -
A6: ETH | B6: 재진입 | C6: 2018.12 | D6: 85 | E6: 1,000,000 | F6: 85 | G6: - | H6: -
A7: ETH | B7: 2차매도 | C7: 2021.11 | D7: 4800 | E7: 1,500,000 | F7: 7200 | G7: - | H7: -
A8: ETH | B8: 재진입 | C8: 2022.06 | D8: 900 | E8: 1,500,000 | F8: 1350 | G8: - | H8: -
A9: ETH | B9: 2024초보유 | C9: 2024 | D9: 2300 | E9: 2,500,000 | F9: 5750 | G9: 8500 | H9: 5750
A10: BNB | B10: 최초매집 | C10: 2017.07 | D10: 0.1 | E10: 10,000,000 | F10: 1 | G10: - | H10: -
A11: BNB | B11: 1차매도 | C11: 2018.01 | D11: 25 | E11: 3,000,000 | F11: 75 | G11: - | H11: -
A12: BNB | B12: 재진입 | C12: 2018.12 | D12: 4 | E12: 3,000,000 | F12: 12 | G12: - | H12: -
A13: BNB | B13: 2차매도 | C13: 2021.05 | D13: 650 | E13: 5,000,000 | F13: 3250 | G13: - | H13: -
A14: BNB | B14: 재진입 | C14: 2022.06 | D14: 180 | E14: 5,000,000 | F14: 900 | G14: - | H14: -
A15: BNB | B15: 2024초보유 | C15: 2024 | D15: 320 | E15: 10,000,000 | F15: 3200 | G15: 5300 | H15: 3200
A16: SOL | B16: 최초매집 | C16: 2020.04 | D16: 0.5 | E16: 5,000,000 | F16: 2.5 | G16: - | H16: -
A17: SOL | B17: 추가매집 | C17: 2020.08 | D17: 3 | E17: 2,000,000 | F17: 6 | G17: - | H17: -
A18: SOL | B18: 1차매도 | C18: 2021.11 | D18: 250 | E18: 3,500,000 | F18: 875 | G18: - | H18: -
A19: SOL | B19: 재진입 | C19: 2022.12 | D19: 8 | E19: 3,500,000 | F19: 28 | G19: - | H19: -
A20: SOL | B20: 2차매도 | C20: 2023.12 | D20: 110 | E20: 2,000,000 | F20: 220 | G20: - | H20: -
A21: SOL | B21: 2024초보유 | C21: 2024 | D21: 100 | E21: 5,500,000 | F21: 550 | G21: 1900 | H21: 550
A22: XRP | B22: 최초매집 | C22: 2013 | D22: 0.005 | E22: 100,000,000 | F22: 0.5 | G22: - | H22: -
A23: XRP | B23: 추가매집 | C23: 2014~2016 | D23: 0.01 | E23: 50,000,000 | F23: 0.5 | G23: - | H23: -
A24: XRP | B24: 1차매도 | C24: 2018.01 | D24: 3.5 | E24: 80,000,000 | F24: 280 | G24: - | H24: -
A25: XRP | B25: 재진입 | C25: 2018.12 | D25: 0.25 | E25: 80,000,000 | F25: 20 | G25: - | H25: -
A26: XRP | B26: 2차매도 | C26: 2021.04 | D26: 1.8 | E26: 60,000,000 | F26: 108 | G26: - | H26: -
A27: XRP | B27: 재진입 | C27: 2021.07 | D27: 0.55 | E27: 60,000,000 | F27: 33 | G27: - | H27: -
A28: XRP | B28: 2024초보유 | C28: 2024 | D28: 0.6 | E28: 150,000,000 | F28: 90 | G28: 3900 | H28: 90
A29: LINK | B29: 최초매집 | C29: 2017.09 | D29: 0.11 | E29: 20,000,000 | F29: 2.2 | G29: - | H29: -
A30: LINK | B30: 1차매도 | C30: 2021.05 | D30: 50 | E30: 10,000,000 | F30: 500 | G30: - | H30: -
A31: LINK | B31: 재진입 | C31: 2022.06 | D31: 5.5 | E31: 10,000,000 | F31: 55 | G31: - | H31: -
A32: LINK | B32: 2차매도 | C32: 2023.12 | D32: 18 | E32: 8,000,000 | F32: 144 | G32: - | H32: -
A33: LINK | B33: 2024초보유 | C33: 2024 | D33: 15 | E33: 22,000,000 | F33: 330 | G33: 2100 | H33: 330

Sheet 부동산 보유 현황
A1: K — 부동산 보유 현황 (건물)
A2: 물건 | B2: 위치 | C2: 매입시기 | D2: 매입가 ($M) | E2: 지상 (층) | F2: 지하 (층) | G2: 대지 (㎡) | H2: 건평 (㎡) | I2: 매도시기 | J2: 매도가 ($M) | K2: 수익 ($M) | L2: 현재추정가 ($M) | M2: 임대수익 (연 $M) | N2: 현재상태
A3: 런던 시티 오피스 | B3: 영국 런던 | C3: 2002 | D3: 15 | E3: 22 | F3: 3 | G3: 1200 | H3: 8500 | I3: 2007 | J3: 45 | K3: 30 | N3: 매각완료
A4: 취리히 금융구역 오피스 | B4: 스위스 취리히 | C4: 2002 | D4: 12 | E4: 18 | F4: 2 | G4: 980 | H4: 6200 | I4: 2007 | J4: 35 | K4: 23 | N4: 매각완료
A5: 파리 라데팡스 오피스 | B5: 프랑스 파리 | C5: 2003 | D5: 18 | E5: 25 | F5: 3 | G5: 1500 | H5: 11000 | I5: 2007 | J5: 52 | K5: 34 | N5: 매각완료
A6: 뉴욕 맨해튼 오피스 | B6: 미국 뉴욕 | C6: 2003 | D6: 30 | E6: 32 | F6: 4 | G6: 1800 | H6: 18500 | I6: 2007 | J6: 85 | K6: 55 | N6: 매각완료
A7: 시카고 루프 오피스 | B7: 미국 시카고 | C7: 2003 | D7: 20 | E7: 24 | F7: 3 | G7: 1400 | H7: 12000 | I7: 2007 | J7: 55 | K7: 35 | N7: 매각완료
A8: LA 다운타운 오피스 | B8: 미국 LA | C8: 2003 | D8: 18 | E8: 20 | F8: 2 | G8: 1300 | H8: 10500 | I8: 2007 | J8: 48 | K8: 30 | N8: 매각완료
A9: 재진입 뉴욕 오피스 | B9: 미국 뉴욕 | C9: 2009 | D9: 40 | E9: 28 | F9: 4 | G9: 1600 | H9: 16000 | I9: 2019 | J9: 180 | K9: 140 | N9: 매각완료
A10: 재진입 LA 오피스 | B10: 미국 LA | C10: 2009 | D10: 25 | E10: 18 | F10: 2 | G10: 1200 | H10: 9500 | I10: 2019 | J10: 95 | K10: 70 | N10: 매각완료
A11: 재진입 런던 오피스 | B11: 영국 런던 | C11: 2009 | D11: 25 | E11: 20 | F11: 3 | G11: 1100 | H11: 8800 | I11: 2015 | J11: 80 | K11: 55 | N11: 매각완료
A12: 재진입 취리히 오피스 | B12: 스위스 취리히 | C12: 2009 | D12: 20 | E12: 16 | F12: 2 | G12: 900 | H12: 6000 | I12: 2015 | J12: 60 | K12: 40 | N12: 매각완료
A13: 홍콩 센트럴 오피스 | B13: 홍콩 | C13: 2004 | D13: 20 | E13: 30 | F13: 4 | G13: 850 | H13: 12000 | I13: 2018 | J13: 120 | K13: 100 | N13: 매각완료
A14: 싱가포르 CBD 오피스 | B14: 싱가포르 | C14: 2004 | D14: 15 | E14: 24 | F14: 3 | G14: 780 | H14: 9500 | I14: 2018 | J14: 85 | K14: 70 | N14: 매각완료
... A16: 마이애미 상업용 | B16: 미국 마이애미 | C16: 2012 | D16: 35 | E16: 12 | F16: 2 | G16: 2200 | H16: 7500 | I16: 2022 | J16: 160 | K16: 125 | N16: 매각완료
A17: 뉴욕 맨해튼 펜트하우스 | B17: 미국 뉴욕 | C17: 2015 | D17: 50 | E17: 65 | F17: 5 | G17: 420 | H17: 3200 | I17: - | L17: 120 | M17: 1.2 | N17: 보유중
A18: 런던 메이페어 빌딩 | B18: 영국 런던 | C18: 2016 | D18: 60 | E18: 8 | F18: 2 | G18: 1800 | H18: 5500 | I18: - | L18: 140 | M18: 2.8 | N18: 보유중
A19: 싱가포르 센토사 복합빌딩 | B19: 싱가포르 | C19: 2017 | D19: 45 | E19: 15 | F19: 3 | G19: 3500 | H19: 12000 | I19: - | L19: 95 | M19: 3.5 | N19: 보유중
A20: 서울 강남 빌딩 | B20: 한국 서울 | C20: 2010 | D20: 30 | E20: 12 | F20: 3 | G20: 1100 | H20: 6800 | I20: - | L20: 180 | M20: 4.2 | N20: 보유중
A21: 도쿄 롯폰기 오피스 | B21: 일본 도쿄 | C21: 2018 | D21: 40 | E21: 18 | F21: 4 | G21: 980 | H21: 9200 | I21: - | L21: 85 | M21: 2.1 | N21: 보유중
A22: 건물 누적 매각 수익 합계 | K22: =SUM(K3:K21)
A23: 현재 보유 건물 추정가 합계 | L23: =SUMIF(N3:N21,"보유중",L3:L21)
A24: 현재 보유 건물 연 임대수익 합계 | M24: =SUMIF(N3:N21,"보유중",M3:M21)
A27: K — 토지 보유 현황
A28: 물건명 | B28: 위치 | C28: 용도 | D28: 매입시기 | E28: 매입가 ($M) | F28: 면적 (㎡) | G28: 지목 | H28: 매도시기 | I28: 매도가 ($M) | J28: 수익 ($M) | K28: 현재추정가 ($M) | L28: 현재상태
A29: 뉴욕 브루클린 개발부지 | B29: 미국 뉴욕 브루클린 | C29: 개발용 | D29: 2008 | E29: 35 | F29: 28000 | G29: 대지 | H29: - | K29: 95 | L29: 보유중
A30: 런던 이스트엔드 개발부지 | B30: 영국 런던 이스트엔드 | C30: 개발용 | D30: 2010 | E30: 28 | F30: 18500 | G30: 대지 | H30: - | K30: 110 | L30: 보유중
A31: 싱가포르 주롱 개발부지 | B31: 싱가포르 주롱 | C31: 개발용 | D31: 2011 | E31: 22 | F31: 32000 | G31: 대지 | H31: - | K31: 85 | L31: 보유중
A32: 서울 마곡 개발부지 | B32: 한국 서울 마곡 | C32: 개발용 | D32: 2009 | E32: 15 | F32: 12000 | G32: 대지 | H32: - | K32: 180 | L32: 보유중
A33: 도쿄 시나가와 개발부지 | B33: 일본 도쿄 시나가와 | C33: 개발용 | D33: 2012 | E33: 30 | F33: 8500 | G33: 대지 | H33: - | K33: 120 | L33: 보유중
A34: 두바이 다운타운 개발부지 | B34: UAE 두바이 | C34: 개발용 | D34: 2014 | E34: 45 | F34: 55000 | G34: 대지 | H34: - | K34: 160 | L34: 보유중
A35: 베트남 하노이 개발부지 | B35: 베트남 하노이 | C35: 개발용 | D35: 2015 | E35: 18 | F35: 85000 | G35: 전 | H35: - | K35: 95 | L35: 보유중
A36: 인도네시아 자카르타 부지 | B36: 인도네시아 자카르타 | C36: 개발용 | D36: 2016 | E36: 20 | F36: 120000 | G36: 대지 | H36: - | K36: 88 | L36: 보유중
A37: 맨해튼 미드타운 나대지 | B37: 미국 뉴욕 맨해튼 | C37: 나대지 | D37: 2003 | E37: 25 | F37: 3200 | G37: 대지 | H37: 2011 | I37: 95 | J37: 70 | L37: 매각완료
A38: 시드니 CBD 나대지 | B38: 호주 시드니 | C38: 나대지 | D38: 2007 | E38: 18 | F38: 4500 | G38: 대지 | H38: 2015 | I38: 72 | J38: 54 | L38: 매각완료
A39: 파리 8구 나대지 | B39: 프랑스 파리 8구 | C39: 나대지 | D39: 2005 | E39: 22 | F39: 2800 | G39: 대지 | H39: 2013 | I39: 88 | J39: 66 | L39: 매각완료
A40: 홍콩 카오룽 나대지 | B40: 홍콩 카오룽 | C40: 나대지 | D40: 2008 | E40: 30 | F40: 5500 | G40: 대지 | H40: 2017 | I40: 145 | J40: 115 | L40: 매각완료
A41: 서울 강남 나대지 | B41: 한국 서울 강남 | C41: 나대지 | D41: 2006 | E41: 12 | F41: 2200 | G41: 대지 | H41: - | K41: 220 | L41: 보유중
A42: 부산 해운대 나대지 | B42: 한국 부산 해운대 | C42: 나대지 | D42: 2010 | E42: 8 | F42: 8500 | G42: 대지 | H42: - | K42: 65 | L42: 보유중
A43: 도쿄 미나토 나대지 | B43: 일본 도쿄 미나토 | C43: 나대지 | D43: 2013 | E43: 20 | F43: 3800 | G43: 대지 | H43: - | K43: 95 | L43: 보유중
...
